<?xml version="1.0" ?>
<!-- =================================================================================== -->
<!-- |    This document was autogenerated by xacro from robomaster_s1.urdf.xacro       | -->
<!-- |    EDITING THIS FILE BY HAND IS NOT RECOMMENDED                                 | -->
<!-- =================================================================================== -->
<robot name="robomaster_s1">
  <link name="base_link"/>
  <link name="chassis_base_link">
    <inertial>
      <origin rpy="0 0 0" xyz="-0.0058789 -0.0001128 0.0294307"/>
      <mass value="1.934"/>
      <inertia ixx="0.01451" ixy="0" ixz="0" iyy="0.00512" iyz="0" izz="0.01759"/>
    </inertial>
    <visual name="armor">
      <origin rpy="0 0 0" xyz="-0.0064553 -0.078141 0.0292877"/>
      <geometry>
        <mesh filename="package://robomaster_description/meshes/armor.dae" scale="1.0 1.0 1.0"/>
      </geometry>
      <material name="armor_plastic"/>
    </visual>
    <visual name="battery">
      <origin rpy="0 0 0" xyz="-0.130336 -0.0018702 0.0174177"/>
      <geometry>
        <mesh filename="package://robomaster_description/meshes/battery.dae" scale="1.0 1.0 1.0"/>
      </geometry>
      <material name="dark_plastic"/>
    </visual>
    <visual name="battery_pin_left">
      <origin rpy="0 0 0" xyz="-0.1158907 0.066115 0.0525243"/>
      <geometry>
        <mesh filename="package://robomaster_description/meshes/battery_pin_left.dae" scale="1.0 1.0 1.0"/>
      </geometry>
      <material name="dark_plastic"/>
    </visual>
    <visual name="battery_pin_right">
      <origin rpy="0 0 0" xyz="-0.1158907 -0.0658844 0.0525243"/>
      <geometry>
        <mesh filename="package://robomaster_description/meshes/battery_pin_right.dae" scale="1.0 1.0 1.0"/>
      </geometry>
      <material name="dark_plastic"/>
    </visual>
    <visual name="chassis">
      <origin rpy="0 0 0" xyz="-0.0059039 0.0004154 0.0527955"/>
      <geometry>
        <mesh filename="package://robomaster_description/meshes/chassis.dae" scale="1.0 1.0 1.0"/>
      </geometry>
      <material name="chassis"/>
    </visual>
    <visual name="controller">
      <origin rpy="0 0 0" xyz="-0.1142288 -0.0006716 0.052675"/>
      <geometry>
        <mesh filename="package://robomaster_description/meshes/controller.dae" scale="1.0 1.0 1.0"/>
      </geometry>
      <material name="dark_plastic"/>
    </visual>
    <visual name="controller_cover">
      <origin rpy="0 0 0" xyz="-0.0787757 -0.002522 0.0720827"/>
      <geometry>
        <mesh filename="package://robomaster_description/meshes/controller_cover.dae" scale="1.0 1.0 1.0"/>
      </geometry>
      <material name="cover_plastic"/>
    </visual>
    <collision name="base_collision">
      <origin rpy="0 0 0" xyz="-0.0058789 -0.0001128 0.0294307"/>
      <geometry>
        <mesh filename="package://robomaster_description/meshes/base_collision.dae" scale="1.0 1.0 1.0"/>
      </geometry>
    </collision>
  </link>
  <joint name="chassis_base_joint" type="fixed">
    <origin rpy="0 0 0" xyz="0 0 0.03465"/>
    <parent link="base_link"/>
    <child link="chassis_base_link"/>
  </joint>
  <link name="front_hit_sensor_link">
    <inertial>
      <origin rpy="0 0 0" xyz="0 0 0"/>
      <mass value="0.001"/>
      <inertia ixx="0.001" ixy="0" ixz="0" iyy="0.001" iyz="0" izz="0.001"/>
    </inertial>
    <visual name="front_hit_sensor">
      <origin rpy="0 0 0" xyz="0 0 0"/>
      <geometry>
        <mesh filename="package://robomaster_description/meshes/hit_sensor.dae" scale="1.0 1.0 1.0"/>
      </geometry>
      <material name="hit_detector"/>
    </visual>
  </link>
  <link name="front_led_link">
    <inertial>
      <origin rpy="0 0 0" xyz="0 0 0"/>
      <mass value="0.001"/>
      <inertia ixx="0.001" ixy="0" ixz="0" iyy="0.001" iyz="0" izz="0.001"/>
    </inertial>
    <visual name="front_led">
      <origin rpy="0 0 0" xyz="0 0 0"/>
      <geometry>
        <mesh filename="package://robomaster_description/meshes/led.dae" scale="1.0 1.0 1.0"/>
      </geometry>
      <material name="led_light"/>
    </visual>
  </link>
  <joint name="front_hit_sensor_joint" type="fixed">
    <origin rpy="0 0 0" xyz="0.1569985 -0.0004276 0.0432862"/>
    <parent link="chassis_base_link"/>
    <child link="front_hit_sensor_link"/>
  </joint>
  <joint name="front_led_joint" type="fixed">
    <origin rpy="0 0 0" xyz="0.0087428 -0.0012841 3.75e-05"/>
    <parent link="front_hit_sensor_link"/>
    <child link="front_led_link"/>
  </joint>
  <link name="left_hit_sensor_link">
    <inertial>
      <origin rpy="0 0 0" xyz="0 0 0"/>
      <mass value="0.001"/>
      <inertia ixx="0.001" ixy="0" ixz="0" iyy="0.001" iyz="0" izz="0.001"/>
    </inertial>
    <visual name="left_hit_sensor">
      <origin rpy="0 0 0" xyz="0 0 0"/>
      <geometry>
        <mesh filename="package://robomaster_description/meshes/hit_sensor.dae" scale="1.0 1.0 1.0"/>
      </geometry>
      <material name="hit_detector"/>
    </visual>
  </link>
  <link name="left_led_link">
    <inertial>
      <origin rpy="0 0 0" xyz="0 0 0"/>
      <mass value="0.001"/>
      <inertia ixx="0.001" ixy="0" ixz="0" iyy="0.001" iyz="0" izz="0.001"/>
    </inertial>
    <visual name="left_led">
      <origin rpy="0 0 0" xyz="0 0 0"/>
      <geometry>
        <mesh filename="package://robomaster_description/meshes/led.dae" scale="1.0 1.0 1.0"/>
      </geometry>
      <material name="led_light"/>
    </visual>
  </link>
  <joint name="left_hit_sensor_joint" type="fixed">
    <origin rpy="0 0 1.5707963267948966" xyz="-0.0024413 0.0886932 0.0298341"/>
    <parent link="chassis_base_link"/>
    <child link="left_hit_sensor_link"/>
  </joint>
  <joint name="left_led_joint" type="fixed">
    <origin rpy="0 0 0" xyz="0.0087428 -0.0012841 3.75e-05"/>
    <parent link="left_hit_sensor_link"/>
    <child link="left_led_link"/>
  </joint>
  <link name="rear_hit_sensor_link">
    <inertial>
      <origin rpy="0 0 0" xyz="0 0 0"/>
      <mass value="0.001"/>
      <inertia ixx="0.001" ixy="0" ixz="0" iyy="0.001" iyz="0" izz="0.001"/>
    </inertial>
    <visual name="rear_hit_sensor">
      <origin rpy="0 0 0" xyz="0 0 0"/>
      <geometry>
        <mesh filename="package://robomaster_description/meshes/hit_sensor.dae" scale="1.0 1.0 1.0"/>
      </geometry>
      <material name="hit_detector"/>
    </visual>
  </link>
  <link name="rear_led_link">
    <inertial>
      <origin rpy="0 0 0" xyz="0 0 0"/>
      <mass value="0.001"/>
      <inertia ixx="0.001" ixy="0" ixz="0" iyy="0.001" iyz="0" izz="0.001"/>
    </inertial>
    <visual name="rear_led">
      <origin rpy="0 0 0" xyz="0 0 0"/>
      <geometry>
        <mesh filename="package://robomaster_description/meshes/led.dae" scale="1.0 1.0 1.0"/>
      </geometry>
      <material name="led_light"/>
    </visual>
  </link>
  <joint name="rear_hit_sensor_joint" type="fixed">
    <origin rpy="0 0 3.141592653589793" xyz="-0.1581827 -0.0027864 0.0303668"/>
    <parent link="chassis_base_link"/>
    <child link="rear_hit_sensor_link"/>
  </joint>
  <joint name="rear_led_joint" type="fixed">
    <origin rpy="0 0 0" xyz="0.0087428 -0.0012841 3.75e-05"/>
    <parent link="rear_hit_sensor_link"/>
    <child link="rear_led_link"/>
  </joint>
  <link name="right_hit_sensor_link">
    <inertial>
      <origin rpy="0 0 0" xyz="0 0 0"/>
      <mass value="0.001"/>
      <inertia ixx="0.001" ixy="0" ixz="0" iyy="0.001" iyz="0" izz="0.001"/>
    </inertial>
    <visual name="right_hit_sensor">
      <origin rpy="0 0 0" xyz="0 0 0"/>
      <geometry>
        <mesh filename="package://robomaster_description/meshes/hit_sensor.dae" scale="1.0 1.0 1.0"/>
      </geometry>
      <material name="hit_detector"/>
    </visual>
  </link>
  <link name="right_led_link">
    <inertial>
      <origin rpy="0 0 0" xyz="0 0 0"/>
      <mass value="0.001"/>
      <inertia ixx="0.001" ixy="0" ixz="0" iyy="0.001" iyz="0" izz="0.001"/>
    </inertial>
    <visual name="right_led">
      <origin rpy="0 0 0" xyz="0 0 0"/>
      <geometry>
        <mesh filename="package://robomaster_description/meshes/led.dae" scale="1.0 1.0 1.0"/>
      </geometry>
      <material name="led_light"/>
    </visual>
  </link>
  <joint name="right_hit_sensor_joint" type="fixed">
    <origin rpy="0 0 -1.5707963267948966" xyz="-0.0024413 -0.0886932 0.0298341"/>
    <parent link="chassis_base_link"/>
    <child link="right_hit_sensor_link"/>
  </joint>
  <joint name="right_led_joint" type="fixed">
    <origin rpy="0 0 0" xyz="0.0087428 -0.0012841 3.75e-05"/>
    <parent link="right_hit_sensor_link"/>
    <child link="right_led_link"/>
  </joint>
  <link name="front_left_wheel_link">
    <inertial>
      <origin rpy="0 0 0" xyz="-0.0002104 5.31e-05 -0.0004148"/>
      <mass value="0.162"/>
      <inertia ixx="0.0002" ixy="0" ixz="0" iyy="0.00012" iyz="0" izz="0.00012"/>
    </inertial>
    <visual name="front_left_wheel_bolt">
      <origin rpy="1.5707963267948966 0 0" xyz="0 0.0145 0"/>
      <geometry>
        <cylinder length="0.001" radius="0.007"/>
      </geometry>
      <material name="bolt">
        <color rgba="0.45 0.15 0.0 1.0"/>
      </material>
    </visual>
    <visual name="front_left_wheel">
      <origin rpy="0 0 0" xyz="0 0 0"/>
      <geometry>
        <mesh filename="package://robomaster_description/meshes/wheel.dae" scale="1.0 1 1.0"/>
      </geometry>
      <material name="wheel_plastic"/>
    </visual>
    <collision name="front_left_wheel">
      <origin rpy="1.5707963267948966 0 0" xyz="0 0 0"/>
      <geometry>
        <cylinder length="0.042" radius="0.05"/>
      </geometry>
      <material name="collision">
        <color rgba="0.8 0.0 0.0 1.0"/>
      </material>
    </collision>
  </link>
  <joint name="front_left_wheel_joint" type="continuous">
    <origin rpy="0 0 0" xyz="0.1 0.1 0.01535"/>
    <parent link="chassis_base_link"/>
    <child link="front_left_wheel_link"/>
    <axis xyz="0 1.0 0"/>
    <limit effort="0" velocity="0"/>
  </joint>
  <link name="front_right_wheel_link">
    <inertial>
      <origin rpy="0 0 0" xyz="-0.0002104 5.31e-05 -0.0004148"/>
      <mass value="0.162"/>
      <inertia ixx="0.0002" ixy="0" ixz="0" iyy="0.00012" iyz="0" izz="0.00012"/>
    </inertial>
    <visual name="front_right_wheel_bolt">
      <origin rpy="1.5707963267948966 0 0" xyz="0 -0.0145 0"/>
      <geometry>
        <cylinder length="0.001" radius="0.007"/>
      </geometry>
      <material name="bolt">
        <color rgba="0.45 0.15 0.0 1.0"/>
      </material>
    </visual>
    <visual name="front_right_wheel">
      <origin rpy="0 0 0" xyz="0 0 0"/>
      <geometry>
        <mesh filename="package://robomaster_description/meshes/wheel.dae" scale="1.0 -1 1.0"/>
      </geometry>
      <material name="wheel_plastic"/>
    </visual>
    <collision name="front_right_wheel">
      <origin rpy="1.5707963267948966 0 0" xyz="0 0 0"/>
      <geometry>
        <cylinder length="0.042" radius="0.05"/>
      </geometry>
      <material name="collision">
        <color rgba="0.8 0.0 0.0 1.0"/>
      </material>
    </collision>
  </link>
  <joint name="front_right_wheel_joint" type="continuous">
    <origin rpy="0 0 0" xyz="0.1 -0.1 0.01535"/>
    <parent link="chassis_base_link"/>
    <child link="front_right_wheel_link"/>
    <axis xyz="0 1.0 0"/>
    <limit effort="0" velocity="0"/>
  </joint>
  <link name="rear_left_wheel_link">
    <inertial>
      <origin rpy="0 0 0" xyz="-0.0002104 5.31e-05 -0.0004148"/>
      <mass value="0.162"/>
      <inertia ixx="0.0002" ixy="0" ixz="0" iyy="0.00012" iyz="0" izz="0.00012"/>
    </inertial>
    <visual name="rear_left_wheel_bolt">
      <origin rpy="1.5707963267948966 0 0" xyz="0 0.0145 0"/>
      <geometry>
        <cylinder length="0.001" radius="0.007"/>
      </geometry>
      <material name="bolt">
        <color rgba="0.45 0.15 0.0 1.0"/>
      </material>
    </visual>
    <visual name="rear_left_wheel">
      <origin rpy="0 0 0" xyz="0 0 0"/>
      <geometry>
        <mesh filename="package://robomaster_description/meshes/wheel.dae" scale="1.0 -1 1.0"/>
      </geometry>
      <material name="wheel_plastic"/>
    </visual>
    <collision name="rear_left_wheel">
      <origin rpy="1.5707963267948966 0 0" xyz="0 0 0"/>
      <geometry>
        <cylinder length="0.042" radius="0.05"/>
      </geometry>
      <material name="collision">
        <color rgba="0.8 0.0 0.0 1.0"/>
      </material>
    </collision>
  </link>
  <joint name="rear_left_wheel_joint" type="continuous">
    <origin rpy="0 0 0" xyz="-0.1 0.1 0.01535"/>
    <parent link="chassis_base_link"/>
    <child link="rear_left_wheel_link"/>
    <axis xyz="0 1.0 0"/>
    <limit effort="0" velocity="0"/>
  </joint>
  <link name="rear_right_wheel_link">
    <inertial>
      <origin rpy="0 0 0" xyz="-0.0002104 5.31e-05 -0.0004148"/>
      <mass value="0.162"/>
      <inertia ixx="0.0002" ixy="0" ixz="0" iyy="0.00012" iyz="0" izz="0.00012"/>
    </inertial>
    <visual name="rear_right_wheel_bolt">
      <origin rpy="1.5707963267948966 0 0" xyz="0 -0.0145 0"/>
      <geometry>
        <cylinder length="0.001" radius="0.007"/>
      </geometry>
      <material name="bolt">
        <color rgba="0.45 0.15 0.0 1.0"/>
      </material>
    </visual>
    <visual name="rear_right_wheel">
      <origin rpy="0 0 0" xyz="0 0 0"/>
      <geometry>
        <mesh filename="package://robomaster_description/meshes/wheel.dae" scale="1.0 1 1.0"/>
      </geometry>
      <material name="wheel_plastic"/>
    </visual>
    <collision name="rear_right_wheel">
      <origin rpy="1.5707963267948966 0 0" xyz="0 0 0"/>
      <geometry>
        <cylinder length="0.042" radius="0.05"/>
      </geometry>
      <material name="collision">
        <color rgba="0.8 0.0 0.0 1.0"/>
      </material>
    </collision>
  </link>
  <joint name="rear_right_wheel_joint" type="continuous">
    <origin rpy="0 0 0" xyz="-0.1 -0.1 0.01535"/>
    <parent link="chassis_base_link"/>
    <child link="rear_right_wheel_link"/>
    <axis xyz="0 1.0 0"/>
    <limit effort="0" velocity="0"/>
  </joint>
  <material name="armor_plastic">
    <color rgba="0.2277128 0.2277128 0.2277128 0.8"/>
  </material>
  <material name="chassis">
    <color rgba="0.0981132 0.0981132 0.0981132 1.0"/>
  </material>
  <material name="cover_plastic">
    <color rgba="0.2548322 0.2548322 0.2548322 0.30000000000000004"/>
  </material>
  <material name="dark_plastic">
    <color rgba="0.0281746 0.0281746 0.0281746 1.0"/>
  </material>
  <material name="metal">
    <color rgba="0.0281746 0.028 0.0281746 1.0"/>
  </material>
  <material name="hit_detector">
    <color rgba="0.1697846 0.1697846 0.1697846 1.0"/>
  </material>
  <material name="led_light">
    <color rgba="0 0.7773585 0.7773583 1.0"/>
  </material>
  <material name="wheel_plastic">
    <color rgba="0.2739087 0.2739087 0.2739087 1.0"/>
  </material>
  <material name="EP_up.001">
    <color rgba="0.0284811 0.0284811 0.0284811 1.0"/>
  </material>
  <link name="blaster_link">
    <inertial>
      <origin rpy="0 0 0" xyz="0.03675 0.00135 -0.01024"/>
      <mass value="0.1"/>
      <inertia ixx="5e-05" ixy="0" ixz="0" iyy="0.00044" iyz="0" izz="0.00043"/>
    </inertial>
    <visual name="blaster_bug">
      <origin rpy="0 0 0" xyz="0.00029 -0.03927 0.00764"/>
      <geometry>
        <mesh filename="package://robomaster_description/meshes/blaster_bug.dae" scale="0.7949 0.7949 0.7949"/>
      </geometry>
      <material name="gimbal_armor"/>
    </visual>
    <visual name="blaster_gun">
      <origin rpy="0 0 0" xyz="0.03896 0.00326 -0.01071"/>
      <geometry>
        <mesh filename="package://robomaster_description/meshes/blaster_gun.dae" scale="1.0 1.0 1.0"/>
      </geometry>
    </visual>
    <visual name="blaster_magazin">
      <origin rpy="0 0 0" xyz="-0.02031 1e-05 0.02866"/>
      <geometry>
        <mesh filename="package://robomaster_description/meshes/blaster_magazin.dae" scale="1.0 1.0 1.0"/>
      </geometry>
      <material name="plastic"/>
    </visual>
    <visual name="blaster_top">
      <origin rpy="0 0 0" xyz="0.0014 0.00082 0.01703"/>
      <geometry>
        <mesh filename="package://robomaster_description/meshes/blaster_top.dae" scale="1.0 1.0 1.0"/>
      </geometry>
      <material name="gimbal_top"/>
    </visual>
    <collision name="blaster_gun_collision">
      <origin rpy="0 0 0" xyz="0.03675 0.00135 -0.01024"/>
      <geometry>
        <mesh filename="package://robomaster_description/meshes/blaster_gun_collision.dae" scale="1.0 1.0 1.0"/>
      </geometry>
    </collision>
    <collision name="blaster_magazin_collision">
      <origin rpy="0 0 0" xyz="-0.02168 1e-05 0.02911"/>
      <geometry>
        <mesh filename="package://robomaster_description/meshes/blaster_magazin_collision.dae" scale="1.0 1.0 1.0"/>
      </geometry>
    </collision>
    <collision name="blaster_top_collision">
      <origin rpy="0 0 0" xyz="0.00347 0.0008 0.01134"/>
      <geometry>
        <mesh filename="package://robomaster_description/meshes/blaster_top_collision.dae" scale="1.0 1.0 1.0"/>
      </geometry>
    </collision>
  </link>
  <link name="gimbal_base_link">
    <inertial>
      <origin rpy="0 0 0" xyz="-0.00116 -0.00092 -0.00243"/>
      <mass value="0.03"/>
      <inertia ixx="4e-05" ixy="0" ixz="0" iyy="2e-05" iyz="0" izz="6e-05"/>
    </inertial>
    <visual name="gimbal_base">
      <origin rpy="0 0 0" xyz="0 0 0"/>
      <geometry>
        <mesh filename="package://robomaster_description/meshes/gimbal_base.dae" scale="1.0 1.0 1.0"/>
      </geometry>
      <material name="gimbal"/>
    </visual>
    <collision name="gimbal_base_collision">
      <origin rpy="0 0 0" xyz="-0.00116 -0.00092 -0.00243"/>
      <geometry>
        <mesh filename="package://robomaster_description/meshes/gimbal_base_collision.dae" scale="1.0 1.0 1.0"/>
      </geometry>
    </collision>
  </link>
  <link name="gimbal_left_led_link">
    <visual name="gimbal_left_led">
      <origin rpy="0 0 0" xyz="-0.02463 0 0.01615"/>
      <geometry>
        <mesh filename="package://robomaster_description/meshes/gimbal_left_led.dae" scale="1.0 1.0 1.0"/>
      </geometry>
      <material name="led_off"/>
    </visual>
    <visual name="gimbal_left_led_0">
      <origin rpy="0 0 0" xyz="-0.02365 0 -0.01734"/>
      <geometry>
        <mesh filename="package://robomaster_description/meshes/gimbal_left_led_0.dae" scale="1.0 1.0 1.0"/>
      </geometry>
      <material name="led_off"/>
    </visual>
    <visual name="gimbal_left_led_1">
      <origin rpy="0 0 0" xyz="-0.00837 0 -0.02777"/>
      <geometry>
        <mesh filename="package://robomaster_description/meshes/gimbal_left_led_1.dae" scale="1.0 1.0 1.0"/>
      </geometry>
      <material name="led_off"/>
    </visual>
    <visual name="gimbal_left_led_2">
      <origin rpy="0 0 0" xyz="0.01027 0 -0.02687"/>
      <geometry>
        <mesh filename="package://robomaster_description/meshes/gimbal_left_led_2.dae" scale="1.0 1.0 1.0"/>
      </geometry>
      <material name="led_off"/>
    </visual>
    <visual name="gimbal_left_led_3">
      <origin rpy="0 0 0" xyz="0.02428 0 -0.01501"/>
      <geometry>
        <mesh filename="package://robomaster_description/meshes/gimbal_left_led_3.dae" scale="1.0 1.0 1.0"/>
      </geometry>
      <material name="led_off"/>
    </visual>
    <visual name="gimbal_left_led_4">
      <origin rpy="0 0 0" xyz="0.02289 -4e-05 0.01672"/>
      <geometry>
        <mesh filename="package://robomaster_description/meshes/gimbal_left_led_4.dae" scale="1.0 1.0 1.0"/>
      </geometry>
      <material name="led_off"/>
    </visual>
    <visual name="gimbal_left_led_5">
      <origin rpy="0 0 0" xyz="0.00874 0 0.02703"/>
      <geometry>
        <mesh filename="package://robomaster_description/meshes/gimbal_left_led_5.dae" scale="1.0 1.0 1.0"/>
      </geometry>
      <material name="led_off"/>
    </visual>
    <visual name="gimbal_left_led_6">
      <origin rpy="0 0 0" xyz="-0.00951 1e-05 0.02709"/>
      <geometry>
        <mesh filename="package://robomaster_description/meshes/gimbal_left_led_6.dae" scale="1.0 1.0 1.0"/>
      </geometry>
      <material name="led_off"/>
    </visual>
    <visual name="gimbal_left_led_7">
      <origin rpy="0 0 0" xyz="-0.02463 0 0.01615"/>
      <geometry>
        <mesh filename="package://robomaster_description/meshes/gimbal_left_led_7.dae" scale="1.0 1.0 1.0"/>
      </geometry>
      <material name="led_off"/>
    </visual>
  </link>
  <link name="gimbal_right_led_link">
    <visual name="gimbal_right_led_0">
      <origin rpy="0 0 0" xyz="-0.02364 -9e-05 -0.01734"/>
      <geometry>
        <mesh filename="package://robomaster_description/meshes/gimbal_right_led_0.dae" scale="1.0 1.0 1.0"/>
      </geometry>
      <material name="led_off"/>
    </visual>
    <visual name="gimbal_right_led_1">
      <origin rpy="0 0 0" xyz="-0.00837 -0.00011 -0.02778"/>
      <geometry>
        <mesh filename="package://robomaster_description/meshes/gimbal_right_led_1.dae" scale="1.0 1.0 1.0"/>
      </geometry>
      <material name="led_off"/>
    </visual>
    <visual name="gimbal_right_led_2">
      <origin rpy="0 0 0" xyz="0.01027 -0.00011 -0.02687"/>
      <geometry>
        <mesh filename="package://robomaster_description/meshes/gimbal_right_led_2.dae" scale="1.0 1.0 1.0"/>
      </geometry>
      <material name="led_off"/>
    </visual>
    <visual name="gimbal_right_led_3">
      <origin rpy="0 0 0" xyz="0.02428 -0.00011 -0.01501"/>
      <geometry>
        <mesh filename="package://robomaster_description/meshes/gimbal_right_led_3.dae" scale="1.0 1.0 1.0"/>
      </geometry>
      <material name="led_off"/>
    </visual>
    <visual name="gimbal_right_led_4">
      <origin rpy="0 0 0" xyz="0.0229 0.00017 0.01671"/>
      <geometry>
        <mesh filename="package://robomaster_description/meshes/gimbal_right_led_4.dae" scale="1.0 1.0 1.0"/>
      </geometry>
      <material name="led_off"/>
    </visual>
    <visual name="gimbal_right_led_5">
      <origin rpy="0 0 0" xyz="0.00874 8e-05 0.02709"/>
      <geometry>
        <mesh filename="package://robomaster_description/meshes/gimbal_right_led_5.dae" scale="1.0 1.0 1.0"/>
      </geometry>
      <material name="led_off"/>
    </visual>
    <visual name="gimbal_right_led_6">
      <origin rpy="0 0 0" xyz="-0.00957 8e-05 0.02706"/>
      <geometry>
        <mesh filename="package://robomaster_description/meshes/gimbal_right_led_6.dae" scale="1.0 1.0 1.0"/>
      </geometry>
      <material name="led_off"/>
    </visual>
    <visual name="gimbal_right_led_7">
      <origin rpy="0 0 0" xyz="-0.02463 8e-05 0.01615"/>
      <geometry>
        <mesh filename="package://robomaster_description/meshes/gimbal_right_led7.dae" scale="1.0 1.0 1.0"/>
      </geometry>
      <material name="led_off"/>
    </visual>
  </link>
  <link name="gimbal_link">
    <inertial>
      <origin rpy="0 0 0" xyz="-0.01647 -0.05644 0.05429"/>
      <mass value="0.4"/>
      <inertia ixx="0.00262" ixy="-0.00029" ixz="-5e-05" iyy="0.00098" iyz="-6e-05" izz="0.00221"/>
    </inertial>
    <visual name="gimbal">
      <origin rpy="0 0 0" xyz="-2e-05 -0.001 0.03369"/>
      <geometry>
        <mesh filename="package://robomaster_description/meshes/gimbal.dae" scale="1.0 1.0 1.0"/>
      </geometry>
      <material name="gimbal"/>
    </visual>
    <visual name="gimbal_left_armor">
      <origin rpy="0 0 0" xyz="-0.00472 0.06418 0.07122"/>
      <geometry>
        <mesh filename="package://robomaster_description/meshes/gimbal_left_armor.dae" scale="1.0 1.0 1.0"/>
      </geometry>
      <material name="gimbal_armor"/>
    </visual>
    <visual name="gimbal_right_armor">
      <origin rpy="0 0 0" xyz="-0.00527 -0.06277 0.07314"/>
      <geometry>
        <mesh filename="package://robomaster_description/meshes/gimbal_right_armor.dae" scale="1.0 1.0 1.0"/>
      </geometry>
      <material name="gimbal_armor"/>
    </visual>
    <visual name="gimbal_side">
      <origin rpy="0 0 0" xyz="-0.00027 0.00034 0.08755"/>
      <geometry>
        <mesh filename="package://robomaster_description/meshes/gimbal_side.dae" scale="1.0 1.0 1.0"/>
      </geometry>
      <material name="gimbal_side"/>
    </visual>
    <collision name="gimbal_collision">
      <origin rpy="0 0 0" xyz="-0.01647 -0.05644 0.05429"/>
      <geometry>
        <mesh filename="package://robomaster_description/meshes/gimbal_collision.dae" scale="1.0 1.0 1.0"/>
      </geometry>
    </collision>
  </link>
  <link name="speaker_link">
    <inertial>
      <origin rpy="0 0 0" xyz="-0.00408 -0.00356 -0.00071"/>
      <mass value="0.06"/>
      <inertia ixx="2e-05" ixy="0" ixz="0" iyy="4e-05" iyz="0" izz="4e-05"/>
    </inertial>
    <visual name="speaker">
      <origin rpy="0 0 0" xyz="0 0 0"/>
      <geometry>
        <mesh filename="package://robomaster_description/meshes/speaker.dae" scale="1.0 1.0 1.0"/>
      </geometry>
      <!-- <material name="Material #32.001" /> -->
    </visual>
    <collision name="speaker_collision">
      <origin rpy="0 0 0" xyz="-0.00408 -0.00356 -0.00071"/>
      <geometry>
        <mesh filename="package://robomaster_description/meshes/speaker_collision.dae" scale="1.0 1.0 1.0"/>
      </geometry>
    </collision>
  </link>
  <joint name="gimbal_base_joint" type="fixed">
    <origin rpy="0 0 0" xyz="-0.002 0 0.118"/>
    <parent link="base_link"/>
    <child link="gimbal_base_link"/>
  </joint>
  <joint name="blaster_joint" type="revolute">
    <origin rpy="0 0 0" xyz="-0.00027 0.00034 0.08755"/>
    <parent link="gimbal_link"/>
    <child link="blaster_link"/>
    <axis xyz="0 1.0 0"/>
    <!-- [-25, +30] degrees -->
    <limit effort="0" lower="-0.5236" upper="0.4363" velocity="0"/>
  </joint>
  <joint name="gimbal_left_led_joint" type="fixed">
    <origin rpy="0 0 0" xyz="0.00032 0.07079 0.08761"/>
    <parent link="gimbal_link"/>
    <child link="gimbal_left_led_link"/>
  </joint>
  <joint name="gimbal_right_led_joint" type="fixed">
    <origin rpy="0 0 0" xyz="0.00032 -0.06941 0.08761"/>
    <parent link="gimbal_link"/>
    <child link="gimbal_right_led_link"/>
  </joint>
  <joint name="gimbal_joint" type="revolute">
    <origin rpy="0 0 0" xyz="0 0 0"/>
    <parent link="gimbal_base_link"/>
    <child link="gimbal_link"/>
    <axis xyz="0 0 1.0"/>
    <!-- [-250, +250] degrees -->
    <limit effort="0" lower="-4.363" upper="4.363" velocity="0"/>
  </joint>
  <joint name="speaker_joint" type="fixed">
    <origin rpy="0 0 0" xyz="-0.01301 0.00691 -0.06117"/>
    <parent link="blaster_link"/>
    <child link="speaker_link"/>
  </joint>
  <material name="gimbal_top">
    <color rgba="0.47861 0.47861 0.47861 1.0"/>
  </material>
  <material name="led_off">
    <color rgba="0.78118 0.78118 0.78118 1.0"/>
  </material>
  <material name="gimbal_side">
    <color rgba="0.01758 0.01758 0.01758 1.0"/>
  </material>
  <material name="plastic">
    <color rgba="0.76578 0.76578 0.76578 1.0"/>
  </material>
  <material name="gimbal">
    <color rgba="0.12595 0.12595 0.12595 1.0"/>
  </material>
  <material name="gimbal_armor">
    <color rgba="0.06401 0.06401 0.06401 1.0"/>
  </material>
  <link name="camera_link">
    <inertial>
      <origin rpy="0 0 0" xyz="0 0 0"/>
      <mass value="0.001"/>
      <inertia ixx="0.001" ixy="0" ixz="0" iyy="0.001" iyz="0" izz="0.001"/>
    </inertial>
    <visual name="camera">
      <origin rpy="0 -1.7453293 0" xyz="7.15e-05 0 -0.0004056"/>
      <geometry>
        <mesh filename="package://robomaster_description/meshes/camera.dae" scale="1.0 1.0 1.0000001"/>
      </geometry>
      <material name="metal"/>
    </visual>
  </link>
  <link name="camera_optical_link">
    <inertial>
      <origin rpy="0 0 0" xyz="0 0 0"/>
      <mass value="0.001"/>
      <inertia ixx="0.001" ixy="0" ixz="0" iyy="0.001" iyz="0" izz="0.001"/>
    </inertial>
  </link>
  <joint name="camera_joint" type="fixed">
    <origin rpy="0 1.5708 0" xyz="0.0728 0.0 0.0315"/>
    <parent link="blaster_link"/>
    <child link="camera_link"/>
  </joint>
  <joint name="camera_optical_joint" type="fixed">
    <!-- <origin xyz="0.002 0.00 0.004" rpy="0.0872663 0 ${-pi/2}"/> -->
    <!-- <origin xyz="0.002 0.00 0.004" rpy="0.0072663 0 ${-pi/2}"/> -->
    <origin rpy="0.041623 0 -1.5707963267948966" xyz="0.002 0.00 0.004"/>
    <parent link="camera_link"/>
    <child link="camera_optical_link"/>
  </joint>
  <!-- <joint name="camera_optical_link" type="fixed">
      <origin xyz="0 0 0" rpy="0 -0.0872663 0"/>
      <parent link="camera_link"/>
      <child link="camera_optical_link"/>
    </joint> -->
  <link name="intelligent_controller_link">
    <inertial>
      <origin rpy="0 0 0" xyz="0 0 0"/>
      <mass value="0.093"/>
      <inertia ixx="0.001" ixy="0" ixz="0" iyy="0.001" iyz="0" izz="0.001"/>
    </inertial>
    <visual name="intelligent_controller">
      <origin rpy="0 0 0" xyz="0 0 -0.0095231"/>
      <geometry>
        <mesh filename="package://robomaster_description/meshes/intelligent_controller.dae" scale="1.0 1.0 1.0"/>
      </geometry>
      <material name="intelligent_controller"/>
    </visual>
    <visual name="wifi_antenna_left">
      <origin rpy="0 0 0" xyz="-0.0147105 0.0344787 0.0032872"/>
      <geometry>
        <mesh filename="package://robomaster_description/meshes/wifi_antenna_left.dae" scale="1.0 1.0 1.0"/>
      </geometry>
      <material name="intelligent_controller"/>
    </visual>
    <visual name="wifi_antenna_right">
      <origin rpy="0 0 0" xyz="-0.0147125 -0.0351398 0.0042003"/>
      <geometry>
        <mesh filename="package://robomaster_description/meshes/wifi_antenna_right.dae" scale="1.0 1.0 1.0"/>
      </geometry>
      <material name="intelligent_controller"/>
    </visual>
    <collision name="top">
      <origin rpy="0 0 0" xyz="0.0231658 -2.02e-05 -0.0113843"/>
      <geometry>
        <box size="0.108973 0.0591028 0.022915"/>
      </geometry>
    </collision>
  </link>
  <joint name="intelligent_controller_joint" type="fixed">
    <origin rpy="0 0 0" xyz="-0.027 0.0 0.07"/>
    <parent link="blaster_link"/>
    <child link="intelligent_controller_link"/>
  </joint>
  <material name="intelligent_controller">
    <color rgba="0.8 0.8 0.8 1.0"/>
  </material>
</robot>
